Workbook

Sheet Übersicht 2026
A1: Anwesenheits-Übersicht 2026
A2: Abwesenheitstage je Mitarbeiter/in – automatisch aus dem Blatt „Kalender 2026“ berechnet.
A4: Raum | B4: Name | C4: Urlaub | D4: Krank | E4: Dienstreise | F4: Sonstige Abwesenheit | G4: Abwesenheit gesamt
A5: 4030 | B5: Anna Göhler | C5: =COUNTIF('Kalender 2026'!C6:NC6,"U") -> 26 | D5: =COUNTIF('Kalender 2026'!C6:NC6,"K") -> 6 | E5: =COUNTIF('Kalender 2026'!C6:NC6,"D") -> 2 | F5: =COUNTA('Kalender 2026'!C6:NC6)-C5-D5-E5-COUNTIF('Kalender 2026'!C6:NC6,"H") -> 0 | G5: =C5+D5+E5+F5 -> 34
A6: 4030 | B6: Annemarie Weber | C6: =COUNTIF('Kalender 2026'!C7:NC7,"U") -> 8 | D6: =COUNTIF('Kalender 2026'!C7:NC7,"K") -> 13 | E6: =COUNTIF('Kalender 2026'!C7:NC7,"D") -> 5 | F6: =COUNTA('Kalender 2026'!C7:NC7)-C6-D6-E6-COUNTIF('Kalender 2026'!C7:NC7,"H") -> 6 | G6: =C6+D6+E6+F6 -> 32
A7: 4030 | B7: Nathalie Schmidt | C7: =COUNTIF('Kalender 2026'!C8:NC8,"U") -> 11 | D7: =COUNTIF('Kalender 2026'!C8:NC8,"K") -> 7 | E7: =COUNTIF('Kalender 2026'!C8:NC8,"D") -> 0 | F7: =COUNTA('Kalender 2026'!C8:NC8)-C7-D7-E7-COUNTIF('Kalender 2026'!C8:NC8,"H") -> 0 | G7: =C7+D7+E7+F7 -> 18
A8: 4030 | B8: Nico Roßa | C8: =COUNTIF('Kalender 2026'!C9:NC9,"U") -> 27 | D8: =COUNTIF('Kalender 2026'!C9:NC9,"K") -> 8 | E8: =COUNTIF('Kalender 2026'!C9:NC9,"D") -> 4 | F8: =COUNTA('Kalender 2026'!C9:NC9)-C8-D8-E8-COUNTIF('Kalender 2026'!C9:NC9,"H") -> 0 | G8: =C8+D8+E8+F8 -> 39
A9: 4030 | B9: Sandra Lehmann | C9: =COUNTIF('Kalender 2026'!C10:NC10,"U") -> 20 | D9: =COUNTIF('Kalender 2026'!C10:NC10,"K") -> 0 | E9: =COUNTIF('Kalender 2026'!C10:NC10,"D") -> 7 | F9: =COUNTA('Kalender 2026'!C10:NC10)-C9-D9-E9-COUNTIF('Kalender 2026'!C10:NC10,"H") -> 2 | G9: =C9+D9+E9+F9 -> 29
A10: 4030 | B10: Sorenza Di Piazza | C10: =COUNTIF('Kalender 2026'!C11:NC11,"U") -> 21 | D10: =COUNTIF('Kalender 2026'!C11:NC11,"K") -> 0 | E10: =COUNTIF('Kalender 2026'!C11:NC11,"D") -> 0 | F10: =COUNTA('Kalender 2026'!C11:NC11)-C10-D10-E10-COUNTIF('Kalender 2026'!C11:NC11,"H") -> 0 | G10: =C10+D10+E10+F10 -> 21
A11: 4030 | B11: Steffi Jünemann | C11: =COUNTIF('Kalender 2026'!C12:NC12,"U") -> 25 | D11: =COUNTIF('Kalender 2026'!C12:NC12,"K") -> 10 | E11: =COUNTIF('Kalender 2026'!C12:NC12,"D") -> 0 | F11: =COUNTA('Kalender 2026'!C12:NC12)-C11-D11-E11-COUNTIF('Kalender 2026'!C12:NC12,"H") -> 0 | G11: =C11+D11+E11+F11 -> 35
A12: 4031 | B12: Anja Bäßler | C12: =COUNTIF('Kalender 2026'!C14:NC14,"U") -> 0 | D12: =COUNTIF('Kalender 2026'!C14:NC14,"K") -> 0 | E12: =COUNTIF('Kalender 2026'!C14:NC14,"D") -> 0 | F12: =COUNTA('Kalender 2026'!C14:NC14)-C12-D12-E12-COUNTIF('Kalender 2026'!C14:NC14,"H") -> 0 | G12: =C12+D12+E12+F12 -> 0
A13: 4031 | B13: Ha Jenny Nguyen | C13: =COUNTIF('Kalender 2026'!C15:NC15,"U") -> 3 | D13: =COUNTIF('Kalender 2026'!C15:NC15,"K") -> 0 | E13: =COUNTIF('Kalender 2026'!C15:NC15,"D") -> 0 | F13: =COUNTA('Kalender 2026'!C15:NC15)-C13-D13-E13-COUNTIF('Kalender 2026'!C15:NC15,"H") -> 0 | G13: =C13+D13+E13+F13 -> 3
A14: 4031 | B14: Julia Shestukhina | C14: =COUNTIF('Kalender 2026'!C16:NC16,"U") -> 24 | D14: =COUNTIF('Kalender 2026'!C16:NC16,"K") -> 3 | E14: =COUNTIF('Kalender 2026'!C16:NC16,"D") -> 3 | F14: =COUNTA('Kalender 2026'!C16:NC16)-C14-D14-E14-COUNTIF('Kalender 2026'!C16:NC16,"H") -> 0 | G14: =C14+D14+E14+F14 -> 30
A15: 4031 | B15: Juliya Urban | C15: =COUNTIF('Kalender 2026'!C17:NC17,"U") -> 5 | D15: =COUNTIF('Kalender 2026'!C17:NC17,"K") -> 0 | E15: =COUNTIF('Kalender 2026'!C17:NC17,"D") -> 0 | F15: =COUNTA('Kalender 2026'!C17:NC17)-C15-D15-E15-COUNTIF('Kalender 2026'!C17:NC17,"H") -> 0 | G15: =C15+D15+E15+F15 -> 5
A16: 4031 | B16: Magdalena Ortner | C16: =COUNTIF('Kalender 2026'!C18:NC18,"U") -> 13 | D16: =COUNTIF('Kalender 2026'!C18:NC18,"K") -> 0 | E16: =COUNTIF('Kalender 2026'!C18:NC18,"D") -> 0 | F16: =COUNTA('Kalender 2026'!C18:NC18)-C16-D16-E16-COUNTIF('Kalender 2026'!C18:NC18,"H") -> 0 | G16: =C16+D16+E16+F16 -> 13
A17: 4031 | B17: Tabea Rosenau | C17: =COUNTIF('Kalender 2026'!C19:NC19,"U") -> 33 | D17: =COUNTIF('Kalender 2026'!C19:NC19,"K") -> 4 | E17: =COUNTIF('Kalender 2026'!C19:NC19,"D") -> 5 | F17: =COUNTA('Kalender 2026'!C19:NC19)-C17-D17-E17-COUNTIF('Kalender 2026'!C19:NC19,"H") -> 0 | G17: =C17+D17+E17+F17 -> 42
A18: 4027 | B18: Emily Heineking | C18: =COUNTIF('Kalender 2026'!C21:NC21,"U") -> 16 | D18: =COUNTIF('Kalender 2026'!C21:NC21,"K") -> 0 | E18: =COUNTIF('Kalender 2026'!C21:NC21,"D") -> 7 | F18: =COUNTA('Kalender 2026'!C21:NC21)-C18-D18-E18-COUNTIF('Kalender 2026'!C21:NC21,"H") -> 0 | G18: =C18+D18+E18+F18 -> 23
A19: 4027 | B19: Katrin Streicher | C19: =COUNTIF('Kalender 2026'!C22:NC22,"U") -> 6 | D19: =COUNTIF('Kalender 2026'!C22:NC22,"K") -> 0 | E19: =COUNTIF('Kalender 2026'!C22:NC22,"D") -> 28 | F19: =COUNTA('Kalender 2026'!C22:NC22)-C19-D19-E19-COUNTIF('Kalender 2026'!C22:NC22,"H") -> 0 | G19: =C19+D19+E19+F19 -> 34
A20: 4028 | B20: Anh Huy Kevin Ho | C20: =COUNTIF('Kalender 2026'!C24:NC24,"U") -> 13 | D20: =COUNTIF('Kalender 2026'!C24:NC24,"K") -> 9 | E20: =COUNTIF('Kalender 2026'!C24:NC24,"D") -> 0 | F20: =COUNTA('Kalender 2026'!C24:NC24)-C20-D20-E20-COUNTIF('Kalender 2026'!C24:NC24,"H") -> 4 | G20: =C20+D20+E20+F20 -> 26
A21: 4028 | B21: Kristin-Elisabeth Suerbier | C21: =COUNTIF('Kalender 2026'!C25:NC25,"U") -> 31 | D21: =COUNTIF('Kalender 2026'!C25:NC25,"K") -> 0 | E21: =COUNTIF('Kalender 2026'!C25:NC25,"D") -> 0 | F21: =COUNTA('Kalender 2026'!C25:NC25)-C21-D21-E21-COUNTIF('Kalender 2026'!C25:NC25,"H") -> 0 | G21: =C21+D21+E21+F21 -> 31
A22: 4028 | B22: Melanie Paasch | C22: =COUNTIF('Kalender 2026'!C26:NC26,"U") -> 26 | D22: =COUNTIF('Kalender 2026'!C26:NC26,"K") -> 7 | E22: =COUNTIF('Kalender 2026'!C26:NC26,"D") -> 0 | F22: =COUNTA('Kalender 2026'!C26:NC26)-C22-D22-E22-COUNTIF('Kalender 2026'!C26:NC26,"H") -> 0 | G22: =C22+D22+E22+F22 -> 33
A23: 4025 | B23: Julia Gruen | C23: =COUNTIF('Kalender 2026'!C28:NC28,"U") -> 38 | D23: =COUNTIF('Kalender 2026'!C28:NC28,"K") -> 0 | E23: =COUNTIF('Kalender 2026'!C28:NC28,"D") -> 1 | F23: =COUNTA('Kalender 2026'!C28:NC28)-C23-D23-E23-COUNTIF('Kalender 2026'!C28:NC28,"H") -> 0 | G23: =C23+D23+E23+F23 -> 39
A24: 4025 | B24: Pascal Brunk | C24: =COUNTIF('Kalender 2026'!C29:NC29,"U") -> 30 | D24: =COUNTIF('Kalender 2026'!C29:NC29,"K") -> 0 | E24: =COUNTIF('Kalender 2026'!C29:NC29,"D") -> 0 | F24: =COUNTA('Kalender 2026'!C29:NC29)-C24-D24-E24-COUNTIF('Kalender 2026'!C29:NC29,"H") -> 0 | G24: =C24+D24+E24+F24 -> 30
A25: 4025 | B25: Tommy Lehmann | C25: =COUNTIF('Kalender 2026'!C30:NC30,"U") -> 17 | D25: =COUNTIF('Kalender 2026'!C30:NC30,"K") -> 2 | E25: =COUNTIF('Kalender 2026'!C30:NC30,"D") -> 0 | F25: =COUNTA('Kalender 2026'!C30:NC30)-C25-D25-E25-COUNTIF('Kalender 2026'!C30:NC30,"H") -> 0 | G25: =C25+D25+E25+F25 -> 19
A26: 4001 | B26: Denise Vahrenkamp | C26: =COUNTIF('Kalender 2026'!C32:NC32,"U") -> 30 | D26: =COUNTIF('Kalender 2026'!C32:NC32,"K") -> 2 | E26: =COUNTIF('Kalender 2026'!C32:NC32,"D") -> 0 | F26: =COUNTA('Kalender 2026'!C32:NC32)-C26-D26-E26-COUNTIF('Kalender 2026'!C32:NC32,"H") -> 0 | G26: =C26+D26+E26+F26 -> 32
B27: Summe / Ø | C27: =SUM(C5:C26) -> 423 | D27: =SUM(D5:D26) -> 71 | E27: =SUM(E5:E26) -> 62 | F27: =SUM(F5:F26) -> 12 | G27: =SUM(G5:G26) -> 568
B29: Kürzel:
B30: U = Urlaub
B31: K = Krank
B32: D = Dienstreise
B33: Sonstige = Freizeitausgleich, Elternzeit, Berufsschule u. a.
B35: Halbe Bürotage (H) zählen als Anwesenheit und sind nicht in den Abwesenheiten enthalten.

Sheet Kalender 2026
A1: Anwesenheitskalender 2026
A2: Raum | B2: Name | C2: Januar | AH2: Februar | BJ2: März | CO2: April | DS2: Mai | EX2: Juni | GB2: Juli | HG2: August | IL2: September | JP2: Oktober | KU2: November | LY2: Dezember
C3: 1 | D3: 2 | E3: 3 | F3: 4 | G3: 5 | H3: 6 | I3: 7 | J3: 8 | K3: 9 | L3: 10 | M3: 11 | N3: 12 | O3: 13 | P3: 14 | Q3: 15 | R3: 16 | S3: 17 | T3: 18 | U3: 19 | V3: 20 | W3: 21 | X3: 22 | Y3: 23 | Z3: 24 | AA3: 25 | AB3: 26 | AC3: 27 | AD3: 28 | AE3: 29 | AF3: 30 | AG3: 31 | AH3: 1 | AI3: 2 | AJ3: 3 | AK3: 4 | AL3: 5 | AM3: 6 | AN3: 7 | AO3: 8 | AP3: 9 | AQ3: 10 | AR3: 11 | AS3: 12 | AT3: 13 | AU3: 14 | AV3: 15 | AW3: 16 | AX3: 17 | AY3: 18 | AZ3: 19 | BA3: 20 | BB3: 21 | BC3: 22 | BD3: 23 | BE3: 24 | BF3: 25 | BG3: 26 | BH3: 27 | BI3: 28 | BJ3: 1 | BK3: 2 | BL3: 3 | BM3: 4 | BN3: 5 | BO3: 6 | BP3: 7 | BQ3: 8 | BR3: 9 | BS3: 10 | BT3: 11 | BU3: 12 | BV3: 13 | BW3: 14 | BX3: 15 | BY3: 16 | BZ3: 17 | CA3: 18 | CB3: 19 | CC3: 20 | CD3: 21 | CE3: 22 | CF3: 23 | CG3: 24 | CH3: 25 | CI3: 26 | CJ3: 27 | CK3: 28 | CL3: 29 | CM3: 30 | CN3: 31 | CO3: 1 | CP3: 2 | CQ3: 3 | CR3: 4 | CS3: 5 | CT3: 6 | CU3: 7 | CV3: 8 | CW3: 9 | CX3: 10 | CY3: 11 | CZ3: 12 | DA3: 13 | DB3: 14 | DC3: 15 | DD3: 16 | DE3: 17 | DF3: 18 | DG3: 19 | DH3: 20 | DI3: 21 | DJ3: 22 | DK3: 23 | DL3: 24 | DM3: 25 | DN3: 26 | DO3: 27 | DP3: 28 | DQ3: 29 | DR3: 30 | DS3: 1 | DT3: 2 | DU3: 3 | DV3: 4 | DW3: 5 | DX3: 6 | DY3: 7 | DZ3: 8 | EA3: 9 | EB3: 10 | EC3: 11 | ED3: 12 | EE3: 13 | EF3: 14 | EG3: 15 | EH3: 16 | EI3: 17 | EJ3: 18 | EK3: 19 | EL3: 20 | EM3: 21 | EN3: 22 | EO3: 23 | EP3: 24 | EQ3: 25 | ER3: 26 | ES3: 27 | ET3: 28 | EU3: 29 | EV3: 30 | EW3: 31 | EX3: 1 | EY3: 2 | EZ3: 3 | FA3: 4 | FB3: 5 | FC3: 6 | FD3: 7 | FE3: 8 | FF3: 9 | FG3: 10 | FH3: 11 | FI3: 12 | FJ3: 13 | FK3: 14 | FL3: 15 | FM3: 16 | FN3: 17 | FO3: 18 | FP3: 19 | FQ3: 20 | FR3: 21 | FS3: 22 | FT3: 23 | FU3: 24 | FV3: 25 | FW3: 26 | FX3: 27 | FY3: 28 | FZ3: 29 | GA3: 30 | GB3: 1 | GC3: 2 | GD3: 3 | GE3: 4 | GF3: 5 | GG3: 6 | GH3: 7 | GI3: 8 | GJ3: 9 | GK3: 10 | GL3: 11 | GM3: 12 | GN3: 13 | GO3: 14 | GP3: 15 | GQ3: 16 | GR3: 17 | GS3: 18 | GT3: 19 | GU3: 20 | GV3: 21 | GW3: 22 | GX3: 23 | GY3: 24 | GZ3: 25 | HA3: 26 | HB3: 27 | HC3: 28 | HD3: 29 | HE3: 30 | HF3: 31 | HG3: 1 | HH3: 2 | HI3: 3 | HJ3: 4 | HK3: 5 | HL3: 6 | HM3: 7 | HN3: 8 | HO3: 9 | HP3: 10 | HQ3: 11 | HR3: 12 | HS3: 13 | HT3: 14 | HU3: 15 | HV3: 16 | HW3: 17 | HX3: 18 | HY3: 19 | HZ3: 20 | IA3: 21 | IB3: 22 | IC3: 23 | ID3: 24 | IE3: 25 | IF3: 26 | IG3: 27 | IH3: 28 | II3: 29 | IJ3: 30 | IK3: 31 | IL3: 1 | IM3: 2 | IN3: 3 | IO3: 4 | IP3: 5 | IQ3: 6 | IR3: 7 | IS3: 8 | IT3: 9 | IU3: 10 | IV3: 11 | IW3: 12 | IX3: 13 | IY3: 14 | IZ3: 15 | JA3: 16 | JB3: 17 | JC3: 18 | JD3: 19 | JE3: 20 | JF3: 21 | JG3: 22 | JH3: 23 | JI3: 24 | JJ3: 25 | JK3: 26 | JL3: 27 | JM3: 28 | JN3: 29 | JO3: 30 | JP3: 1 | JQ3: 2 | JR3: 3 | JS3: 4 | JT3: 5 | JU3: 6 | JV3: 7 | JW3: 8 | JX3: 9 | JY3: 10 | JZ3: 11 | KA3: 12 | KB3: 13 | KC3: 14 | KD3: 15 | KE3: 16 | KF3: 17 | KG3: 18 | KH3: 19 | KI3: 20 | KJ3: 21 | KK3: 22 | KL3: 23 | KM3: 24 | KN3: 25 | KO3: 26 | KP3: 27 | KQ3: 28 | KR3: 29 | KS3: 30 | KT3: 31 | KU3: 1 | KV3: 2 | KW3: 3 | KX3: 4 | KY3: 5 | KZ3: 6 | LA3: 7 | LB3: 8 | LC3: 9 | LD3: 10 | LE3: 11 | LF3: 12 | LG3: 13 | LH3: 14 | LI3: 15 | LJ3: 16 | LK3: 17 | LL3: 18 | LM3: 19 | LN3: 20 | LO3: 21 | LP3: 22 | LQ3: 23 | LR3: 24 | LS3: 25 | LT3: 26 | LU3: 27 | LV3: 28 | LW3: 29 | LX3: 30 | LY3: 1 | LZ3: 2 | MA3: 3 | MB3: 4 | MC3: 5 | MD3: 6 | ME3: 7 | MF3: 8 | MG3: 9 | MH3: 10 | MI3: 11 | MJ3: 12 | MK3: 13 | ML3: 14 | MM3: 15 | MN3: 16 | MO3: 17 | MP3: 18 | MQ3: 19 | MR3: 20 | MS3: 21 | MT3: 22 | MU3: 23 | MV3: 24 | MW3: 25 | MX3: 26 | MY3: 27 | MZ3: 28 | NA3: 29 | NB3: 30 | NC3: 31
C4: Do | D4: Fr | E4: Sa | F4: So | G4: Mo | H4: Di | I4: Mi | J4: Do | K4: Fr | L4: Sa | M4: So | N4: Mo | O4: Di | P4: Mi | Q4: Do | R4: Fr | S4: Sa | T4: So | U4: Mo | V4: Di | W4: Mi | X4: Do | Y4: Fr | Z4: Sa | AA4: So | AB4: Mo | AC4: Di | AD4: Mi | AE4: Do | AF4: Fr | AG4: Sa | AH4: So | AI4: Mo | AJ4: Di | AK4: Mi | AL4: Do | AM4: Fr | AN4: Sa | AO4: So | AP4: Mo | AQ4: Di | AR4: Mi | AS4: Do | AT4: Fr | AU4: Sa | AV4: So | AW4: Mo | AX4: Di | AY4: Mi | AZ4: Do | BA4: Fr | BB4: Sa | BC4: So | BD4: Mo | BE4: Di | BF4: Mi | BG4: Do | BH4: Fr | BI4: Sa | BJ4: So | BK4: Mo | BL4: Di | BM4: Mi | BN4: Do | BO4: Fr | BP4: Sa | BQ4: So | BR4: Mo | BS4: Di | BT4: Mi | BU4: Do | BV4: Fr | BW4: Sa | BX4: So | BY4: Mo | BZ4: Di | CA4: Mi | CB4: Do | CC4: Fr | CD4: Sa | CE4: So | CF4: Mo | CG4: Di | CH4: Mi | CI4: Do | CJ4: Fr | CK4: Sa | CL4: So | CM4: Mo | CN4: Di | CO4: Mi | CP4: Do | CQ4: Fr | CR4: Sa | CS4: So | CT4: Mo | CU4: Di | CV4: Mi | CW4: Do | CX4: Fr | CY4: Sa | CZ4: So | DA4: Mo | DB4: Di | DC4: Mi | DD4: Do | DE4: Fr | DF4: Sa | DG4: So | DH4: Mo | DI4: Di | DJ4: Mi | DK4: Do | DL4: Fr | DM4: Sa | DN4: So | DO4: Mo | DP4: Di | DQ4: Mi | DR4: Do | DS4: Fr | DT4: Sa | DU4: So | DV4: Mo | DW4: Di | DX4: Mi | DY4: Do | DZ4: Fr | EA4: Sa | EB4: So | EC4: Mo | ED4: Di | EE4: Mi | EF4: Do | EG4: Fr | EH4: Sa | EI4: So | EJ4: Mo | EK4: Di | EL4: Mi | EM4: Do | EN4: Fr | EO4: Sa | EP4: So | EQ4: Mo | ER4: Di | ES4: Mi | ET4: Do | EU4: Fr | EV4: Sa | EW4: So | EX4: Mo | EY4: Di | EZ4: Mi | FA4: Do | FB4: Fr | FC4: Sa | FD4: So | FE4: Mo | FF4: Di | FG4: Mi | FH4: Do | FI4: Fr | FJ4: Sa | FK4: So | FL4: Mo | FM4: Di | FN4: Mi | FO4: Do | FP4: Fr | FQ4: Sa | FR4: So | FS4: Mo | FT4: Di | FU4: Mi | FV4: Do | FW4: Fr | FX4: Sa | FY4: So | FZ4: Mo | GA4: Di | GB4: Mi | GC4: Do | GD4: Fr | GE4: Sa | GF4: So | GG4: Mo | GH4: Di | GI4: Mi | GJ4: Do | GK4: Fr | GL4: Sa | GM4: So | GN4: Mo | GO4: Di | GP4: Mi | GQ4: Do | GR4: Fr | GS4: Sa | GT4: So | GU4: Mo | GV4: Di | GW4: Mi | GX4: Do | GY4: Fr | GZ4: Sa | HA4: So | HB4: Mo | HC4: Di | HD4: Mi | HE4: Do | HF4: Fr | HG4: Sa | HH4: So | HI4: Mo | HJ4: Di | HK4: Mi | HL4: Do | HM4: Fr | HN4: Sa | HO4: So | HP4: Mo | HQ4: Di | HR4: Mi | HS4: Do | HT4: Fr | HU4: Sa | HV4: So | HW4: Mo | HX4: Di | HY4: Mi | HZ4: Do | IA4: Fr | IB4: Sa | IC4: So | ID4: Mo | IE4: Di | IF4: Mi | IG4: Do | IH4: Fr | II4: Sa | IJ4: So | IK4: Mo | IL4: Di | IM4: Mi | IN4: Do | IO4: Fr | IP4: Sa | IQ4: So | IR4: Mo | IS4: Di | IT4: Mi | IU4: Do | IV4: Fr | IW4: Sa | IX4: So | IY4: Mo | IZ4: Di | JA4: Mi | JB4: Do | JC4: Fr | JD4: Sa | JE4: So | JF4: Mo | JG4: Di | JH4: Mi | JI4: Do | JJ4: Fr | JK4: Sa | JL4: So | JM4: Mo | JN4: Di | JO4: Mi | JP4: Do | JQ4: Fr | JR4: Sa | JS4: So | JT4: Mo | JU4: Di | JV4: Mi | JW4: Do | JX4: Fr | JY4: Sa | JZ4: So | KA4: Mo | KB4: Di | KC4: Mi | KD4: Do | KE4: Fr | KF4: Sa | KG4: So | KH4: Mo | KI4: Di | KJ4: Mi | KK4: Do | KL4: Fr | KM4: Sa | KN4: So | KO4: Mo | KP4: Di | KQ4: Mi | KR4: Do | KS4: Fr | KT4: Sa | KU4: So | KV4: Mo | KW4: Di | KX4: Mi | KY4: Do | KZ4: Fr | LA4: Sa | LB4: So | LC4: Mo | LD4: Di | LE4: Mi | LF4: Do | LG4: Fr | LH4: Sa | LI4: So | LJ4: Mo | LK4: Di | LL4: Mi | LM4: Do | LN4: Fr | LO4: Sa | LP4: So | LQ4: Mo | LR4: Di | LS4: Mi | LT4: Do | LU4: Fr | LV4: Sa | LW4: So | LX4: Mo | LY4: Di | LZ4: Mi | MA4: Do | MB4: Fr | MC4: Sa | MD4: So | ME4: Mo | MF4: Di | MG4: Mi | MH4: Do | MI4: Fr | MJ4: Sa | MK4: So | ML4: Mo | MM4: Di | MN4: Mi | MO4: Do | MP4: Fr | MQ4: Sa | MR4: So | MS4: Mo | MT4: Di | MU4: Mi | MV4: Do | MW4: Fr | MX4: Sa | MY4: So | MZ4: Mo | NA4: Di | NB4: Mi | NC4: Do
A5: Raum 4030
A6: 4030 | B6: Anna Göhler | D6: U | AP6: U | AQ6: U | AR6: U | AS6: U | AT6: U | CB6: U | CC6: U | EG6: U | EU6: K | EX6: K | EY6: K | EZ6: K | FA6: K | FB6: K | FI6: U | FN6: D | FO6: D | GY6: U | HM6: U | HZ6: U | IA6: U | ID6: U | IE6: U | IF6: U | IG6: U | IH6: U | MU6: U | MV6: U | MZ6: U | NA6: U | NB6: U | NC6: U
A7: 4030 | B7: Annemarie Weber | D7: U | AW7: FZ | BA7: FZ | DD7: D | DE7: D | DH7: D | DI7: D | DJ7: D | EC7: U | ED7: U | EE7: K | EG7: K | EJ7: K | EK7: K | EL7: K | EN7: K | ER7: K | ES7: K | EU7: K | EX7: K | EY7: K | EZ7: K | FB7: K | FZ7: FZ | GK7: FZ | GN7: FZ | GR7: FZ | HB7: U | HI7: U | HJ7: U | HK7: U | HM7: U
A8: 4030 | B8: Nathalie Schmidt | D8: U | AD8: K | AF8: K | AI8: K | AK8: K | AM8: K | EJ8: U | EK8: U | EL8: U | EM8: U | EN8: U | EY8: K | EZ8: K | HB8: U | HC8: U | HD8: U | HE8: U | HF8: U
A9: 4030 | B9: Nico Roßa | D9: U | AL9: K | AM9: K | AP9: K | AQ9: K | AR9: K | BS9: D | CC9: U | CF9: K | CH9: D | CI9: D | CU9: U | CV9: U | CW9: U | CX9: U | ER9: U | ES9: U | ET9: U | EX9: U | EY9: U | EZ9: U | FA9: U | FE9: U | FL9: D | GW9: K | GX9: K | HW9: U | HX9: U | HZ9: U | ID9: U | IE9: U | IF9: U | IG9: U | IR9: U | IS9: U | MZ9: U | NA9: U | NB9: U
A10: 4030 | B10: Sandra Lehmann | D10: U | AL10: FZ | AM10: U | BZ10: D | EG10: FZ | ER10: U | ES10: U | GN10: U | GO10: U | GP10: U | GQ10: U | GR10: U | GU10: U | GV10: U | GW10: U | GX10: U | GY10: U | HB10: U | HC10: U | HD10: U | HE10: U | HF10: U | JC10: U | JF10: D | JG10: D | JH10: D | JI10: D | JO10: D | JP10: D
A11: 4030 | B11: Sorenza Di Piazza | D11: U | CF11: U | CG11: U | CH11: U | CI11: U | CJ11: U | CM11: U | CN11: U | DR11: U | DV11: U | FP11: U | FS11: U | FT11: U | FU11: U | FV11: U | FW11: U | FZ11: U | GA11: U | GB11: U | GC11: U | GD11: U
A12: 4030 | B12: Steffi Jünemann | D12: U | AX12: K | AY12: K | BF12: U | BG12: U | BH12: U | DR12: U | EC12: K | EG12: U | EN12: U | EY12: K | EZ12: K | FA12: K | FB12: K | FE12: K | FF12: K | FG12: K | FP12: U | FS12: U | GK12: U | HP12: U | HW12: U | IN12: U | IO12: U | IR12: U | IS12: U | IT12: U | IU12: U | IV12: U | MU12: U | MV12: U | MZ12: U | NA12: U | NB12: U | NC12: U
A13: Raum 4031
A14: 4031 | B14: Anja Bäßler
A15: 4031 | B15: Ha Jenny Nguyen | AB15: U | AD15: U | AE15: U
A16: 4031 | B16: Julia Shestukhina | D16: U | G16: U | BZ16: D | CA16: D | CB16: D | CF16: U | CG16: U | CH16: U | CI16: U | CJ16: U | CM16: U | CN16: U | CO16: U | CP16: U | CU16: K | CV16: K | CW16: K | EG16: U | FA16: U | FB16: U | FU16: H | FZ16: U | GA16: U | GB16: U | GC16: U | GD16: U | GN16: U | GO16: U | GP16: U | GQ16: U | GR16: U
A17: 4031 | B17: Juliya Urban | AW17: U | AX17: U | AY17: U | AZ17: U | BA17: U
A18: 4031 | B18: Magdalena Ortner | HI18: U | HJ18: U | HK18: U | HW18: U | HX18: U | HZ18: U | IA18: U | ID18: U | IE18: U | IF18: U | IG18: U | IH18: U
A19: 4031 | B19: Tabea Rosenau | BD19: U | BG19: H | BK19: H | BZ19: K | CA19: K | CB19: K | CC19: K | CU19: U | CV19: U | CW19: U | CX19: U | DC19: D | DD19: D | EG19: U | FE19: D | FF19: D | FG19: D | FZ19: U | GA19: U | GB19: U | GC19: U | GD19: U | GG19: U | GH19: U | GI19: U | GJ19: U | GK19: U | IR19: U | IS19: U | IT19: U | IU19: U | IV19: U | IY19: U | IZ19: U | JA19: U | JB19: U | JC19: U | MT19: U | MU19: U | MV19: U | MZ19: U | NA19: U | NB19: U | NC19: U
A20: Raum 4027
A21: 4027 | B21: Emily Heineking | U21: D | V21: D | AE21: U | AF21: U | AM21: U | AP21: U | AR21: D | AS21: D | EG21: U | FE21: U | FF21: U | FG21: U | FH21: U | FI21: U | FW21: U | HQ21: U | HR21: U | HS21: U | HT21: U | HW21: U | IZ21: D | JA21: D | JB21: D
A22: 4027 | B22: Katrin Streicher | AI22: U | AJ22: U | AK22: U | AL22: U | AM22: U | AY22: D | AZ22: D | BK22: D | BL22: D | BM22: D | CA22: D | CB22: D | CF22: D | CG22: D | CH22: D | CI22: D | CJ22: D | CU22: U | DD22: D | DW22: D | EK22: D | EL22: D | EX22: D | EY22: D | EZ22: D | FA22: D | FB22: D | FE22: D | FF22: D | FG22: D | FH22: D | IZ22: D | JA22: D | JB22: D
A23: Raum 4028
A24: 4028 | B24: Anh Huy Kevin Ho | D24: U | AC24: U | AI24: U | AP24: K | AQ24: K | AR24: K | BY24: K | BZ24: & | CA24: M | CF24: K | CG24: & | CH24: M | CM24: U | CN24: U | CO24: U | CP24: U | CU24: U | CV24: U | CW24: U | CX24: U | EL24: U | GH24: U | GQ24: K | GR24: K | GU24: K | GV24: K
A25: 4028 | B25: Kristin-Elisabeth Suerbier | I25: H | BT25: H | BY25: U | BZ25: U | CA25: U | CB25: U | CC25: U | CF25: U | CG25: U | CH25: U | CI25: U | CJ25: U | CM25: U | CN25: U | CO25: U | CP25: U | CX25: H | DP25: H | DQ25: H | DR25: H | ED25: H | FA25: U | FB25: U | FN25: H | FO25: H | GK25: H | HW25: U | HX25: U | HZ25: U | IA25: U | KH25: U | KI25: U | KJ25: U | KK25: U | KL25: U | KO25: U | KP25: U | KQ25: U | KR25: U | KS25: U
A26: 4028 | B26: Melanie Paasch | D26: U | W26: K | X26: K | Y26: K | AB26: K | AC26: K | AL26: H | AT26: U | BD26: U | BE26: U | BF26: U | BG26: U | BH26: U | CF26: K | CX26: U | DP26: U | DQ26: U | DR26: U | DW26: U | DX26: H | EG26: U | EN26: U | FF26: U | FG26: U | FH26: U | FI26: U | FN26: H | FU26: H | GR26: K | IS26: U | IT26: U | JB26: U | JC26: U | JN26: U | JO26: U | JP26: U | JQ26: U
A27: Raum 4025
A28: 4025 | B28: Julia Gruen | CA28: U | CB28: U | CC28: U | CF28: U | CG28: U | CH28: U | CI28: U | CJ28: U | CM28: U | CN28: U | EJ28: D | HI28: U | HJ28: U | HK28: U | HL28: U | HM28: U | IY28: U | IZ28: U | JA28: U | JB28: U | JC28: U | JF28: U | JG28: U | JH28: U | JI28: U | JJ28: U | JM28: U | JN28: U | KY28: U | KZ28: U | LC28: U | LD28: U | LE28: U | LF28: U | LG28: U | LJ28: U | LK28: U | MV28: U | NC28: U
A29: 4025 | B29: Pascal Brunk | D29: U | G29: U | H29: U | I29: U | J29: U | K29: U | N29: U | O29: U | P29: U | Q29: U | R29: U | U29: U | V29: U | W29: U | X29: U | Y29: U | CU29: U | CV29: U | CW29: U | CX29: U | EU29: U | EX29: U | FN29: U | FO29: U | FP29: U | HP29: U | HQ29: U | HR29: U | HS29: U | HT29: U
A30: 4025 | B30: Tommy Lehmann | D30: U | V30: H | AM30: H | AT30: H | BG30: K | BH30: K | DH30: U | DI30: U | DJ30: U | DK30: U | DL30: U | DO30: U | DP30: U | DQ30: U | DR30: U | EG30: U | GD30: U | IY30: U | IZ30: U | JA30: U | JB30: U | JC30: U
A31: Raum 4001
A32: 4001 | B32: Denise Vahrenkamp | D32: U | G32: U | H32: U | I32: U | J32: K | CB32: K | CI32: U | CJ32: U | ET32: U | EU32: U | ID32: U | IE32: U | IF32: U | IG32: U | IH32: U | KD32: U | KE32: U | KH32: U | KI32: U | KJ32: U | KK32: U | KL32: U | MI32: U | ML32: U | MM32: U | MN32: U | MO32: U | MP32: U | MS32: U | MT32: U | MU32: U | MV32: U
B35: Legende
C36: Büroanwesenheit
C37: Wochenende
C38: Feiertag
C39: U = Urlaub
C40: K = Krank
C41: D = Dienstreise
C42: H = halber Tag Büro
...

Sheet Abwesenheiten-Liste 2026
A1: Abwesenheiten 2026 – chronologische Liste
A2: Jede Zeile ist ein zusammenhängender Abwesenheitszeitraum. Spalten lassen sich über die Filter-Pfeile sortieren und filtern.
A4: Name | B4: Raum | C4: Art | D4: von | E4: bis | F4: Tage
A5: Anh Huy Kevin Ho | B5: 4028 | C5: Urlaub | D5: 46024 | E5: 46024 | F5: 1
A6: Anna Göhler | B6: 4030 | C6: Urlaub | D6: 46024 | E6: 46024 | F6: 1
A7: Annemarie Weber | B7: 4030 | C7: Urlaub | D7: 46024 | E7: 46024 | F7: 1
A8: Denise Vahrenkamp | B8: 4001 | C8: Urlaub | D8: 46024 | E8: 46029 | F8: 4
A9: Julia Shestukhina | B9: 4031 | C9: Urlaub | D9: 46024 | E9: 46027 | F9: 2
A10: Melanie Paasch | B10: 4028 | C10: Urlaub | D10: 46024 | E10: 46024 | F10: 1
A11: Nathalie Schmidt | B11: 4030 | C11: Urlaub | D11: 46024 | E11: 46024 | F11: 1
A12: Nico Roßa | B12: 4030 | C12: Urlaub | D12: 46024 | E12: 46024 | F12: 1
A13: Pascal Brunk | B13: 4025 | C13: Urlaub | D13: 46024 | E13: 46045 | F13: 16
A14: Sandra Lehmann | B14: 4030 | C14: Urlaub | D14: 46024 | E14: 46024 | F14: 1
A15: Sorenza Di Piazza | B15: 4030 | C15: Urlaub | D15: 46024 | E15: 46024 | F15: 1
A16: Steffi Jünemann | B16: 4030 | C16: Urlaub | D16: 46024 | E16: 46024 | F16: 1
... A188: Julia Gruen | B188: 4025 | C188: Urlaub | D188: 46387 | E188: 46387 | F188: 1
